<?xml version="1.0"?>
<robot name="simple_legged_robot" xmlns:xacro="http://ros.org/wiki/xacro">

  <!-- Macro for simple_legged_robot body.  -->
  
  	
  <xacro:include filename="chassis.gazebo" /> 
  	
  	
   <link name = "base_link"/>
   
   <joint name="base_link_to_body_joint" type="fixed">
      <parent link="base_link"/>
      <child link="body_link"/>
    </joint>
     	
  <link name="body_link">
    <inertial>
      <origin xyz="-0.003053 -0.038651 -0.019268" />
      <mass value="0.97559947"/>
      <inertia ixx="3.1081800"  ixy="-0.25460189"  ixz="2.0318174" iyy="6.3787776" iyz="0.16417863" izz="5.3316425" />
    </inertial>
    <visual>
      <!--origin xyz="-0.0235 0 -0.03525" rpy="0 0 0" /-->
      <origin xyz="0 0 0" rpy="0 0 0" />
      <geometry>
        <!--box size="0.102 0.109 0.106" /-->
        <mesh filename="package://yegna_pkg/meshes/body.STL"  scale="1 1 1"/>
      </geometry>
      <material name="Blue">
        <color rgba="0.0 0.0 0.80 1.0"/>
      </material>
    </visual>
    <collision>
      <geometry>
        <mesh filename="package://yegna_pkg/meshes/body_coll.stl"  scale="1 1 1"/>
      </geometry>
    </collision>
  </link>
  
  	
   <link name="camera_head">
    <inertial>
      <origin xyz="0.000064 -0.018565 -0.007667" />
      <mass value="0.15804192"/>
     <inertia ixx="0.1239683"  ixy="0.000078494368"  ixz="0.000007645979" iyy="0.11783781" iyz="0.0012199205" izz="0.1583601" />
    </inertial>
    <visual>
      <origin xyz="0 0 0" rpy="0 0 0" />
      <geometry>
        <!-- box size="0.0634 0.061 0.033" /-->
        <mesh filename="package://yegna_pkg/meshes/head.STL"  scale="1 1 1"/>
      </geometry>
      <material name="Grey">
        <color rgba=".2 1.0 1.0 1.0"/>
      </material>
    </visual>
    <collision>
      <geometry>
        <mesh filename="package://yegna_pkg/meshes/head_coll.stl"  scale="1 1 1"/>
      </geometry>
    </collision>
  </link>
  
   <joint name="camera_head_joint" type="revolute">
         <parent link="neck_link"/>
         <child link="camera_head"/>
         <origin xyz="0 0 0.02715" rpy="-1.5707963 0 1.5707963" />
         <axis xyz="0 0 1" />
      <limit effort="2.8" velocity="5.6548668" lower="-2.6179939" upper="2.6179939" />
      </joint>
      
     <transmission name = "trans_joint_camera_head">
      
        <type> transmission_interface/SimpleTransmission</type>
        <joint name = "camera_head_joint">
           <hardwareInterface>EffortJointInterface</hardwareInterface>
           </joint>
        <actuator name = "moto_joint_head">
        <hardwareInterface>EffortJointInterface</hardwareInterface>   
        <mechanicalReduction>1</mechanicalReduction>
        </actuator>
      </transmission>  
  
    <link name="neck_link">
    <inertial>
      <origin xyz="0.001424 -0.016567 -0.007128" />
      <mass value="0.024357719"/>
     <inertia ixx="0.0051411124"  ixy="-0.00057530255"  ixz="-0.000024729049" iyy="0.0081915737" 
          iyz="-0.000019223094" izz="0.0011379812" />
    </inertial>
    <visual>
      <origin xyz="0 0 0" rpy="0 0 0" />
      <geometry>
        <!--box size="0.045 0.022 0.0325" /-->
        <mesh filename="package://yegna_pkg/meshes/neck.STL"  scale="1 1 1"/>
      </geometry>
      <material name="Grey">
        <color rgba="0.20 0.20 0.20 1.0"/>
      </material>
    </visual>
    <collision>
      <geometry>
        <mesh filename="package://yegna_pkg/meshes/neck_coll.stl"  scale="1 1 1"/>
      </geometry>
    </collision>
  </link>

	   <joint name="neck_to_body_joint" type="revolute">
          <parent link="body_link"/>
          <child link="neck_link"/>
          <origin xyz="0 0 0.0235" rpy="0 0 1.5707963" />
          <axis xyz="0 0 1" />
          <limit effort="2.8" velocity="5.6548668" lower="-2.6179939" upper="2.6179939" />
      </joint>
      
      <transmission name = "trans_joint_neck">
      
        <type> transmission_interface/SimpleTransmission</type>
        <joint name = "neck_to_body_joint">
           <hardwareInterface>EffortJointInterface</hardwareInterface>
           </joint>
        <actuator name = "moto_joint_neck">
        <hardwareInterface>EffortJointInterface</hardwareInterface>   
        <mechanicalReduction>1</mechanicalReduction>
        </actuator>
      </transmission>
	   
	   	
	<link name="body_back_left">
    <inertial>
      <origin xyz="-0.0031158909 0.020443695 -0.019663084" />
      <mass value="0.010"/>
      <inertia ixx="3.1081800"  ixy="-0.25460189"  ixz="2.0318174" iyy="6.3787776" iyz="0.16417863" izz="5.3316425" />
    </inertial>
    <visual>
      <origin xyz="0.0 0.0 0.0" rpy="0 0 0" />
      <geometry>
        <box size="0.001 0.001 0.001"  scale="1 1 1"/>
      </geometry>
      <material name="Grey">
        <color rgba="0.20 0.20 0.20 1.0"/>
      </material>
    </visual>
    <collision>
      <geometry>
        <box size="0.001 0.001 0.001"  scale="1 1 1"/>
      </geometry>
    </collision>

  </link>  
 	  <joint name="body_back_left_joint" type="fixed">
        <parent link="body_link"/>
          <child link="body_back_left"/>
          <origin xyz="0 0.06035 0" rpy="-1.5707963 0 0" />
          <limit effort="2.8" velocity="5.6548668" lower="-2.6179939" upper="2.6179939" />
     </joint>
  
   <link name="left_link">
	    
	    <visual>

                <geometry>
                   <box size = "0.12 0.04 0.04"/>
                     
                </geometry>
               <!-- <origin xyz="0 0 -0.3" rpy="0 1.57075 0" /> -->
               <origin xyz="-0.05 -0.010264050 0.0013935747" />
	     
	    	<material name="Blue">
	    	  <color rgba = "0.0 0.0 0.80 1.0"/>
	    	</material>  
	    </visual>            
  </link> 	 
  
  <joint name="left_link_joint" type="fixed">
    <parent link="body_back_left"/>
    <child link="left_link"/>
    <origin xyz="0 0 0" rpy="0 0 -1.5707963" />
    <axis xyz="0 0 1" />
    <limit effort="2.8" velocity="5.6548668" lower="-2.6179939" upper="2.6179939" />
  </joint> 
 
  
  <link name="left_leg" >
    <inertial>
      <origin xyz="-0.053955 0.006548 -0.000592" />
      <mass value="0.070309794"/>
      <inertia ixx="0.093369608"  ixy="-0.00093567395"  ixz="-0.00023992085" iyx="-0.00093567395" iyy="0.046295534" 
                  iyz="-0.012858493"   izx="-0.00023992085" izy="-0.012858493" izz="0.11351516" />
    </inertial>
    <visual>
      <origin xyz="0 0 0" rpy="0 0 0" />
      <geometry>
        <!--box size="0.093 0.035 0.045"/-->
        <mesh filename="package://yegna_pkg/meshes/tibia_l.STL"  scale="1 1 1"/>
      </geometry>
      <material name="Grey">
        <color rgba="0.20 0.20 0.20 1.0"/>
      </material>
    </visual>
    <collision>
      <geometry>
        <mesh filename="package://yegna_pkg/meshes/tibia_l_coll.stl"  scale="1 1 1"/>
      </geometry>
    </collision>
  </link>
  
  <joint name="left_leg_joint" type="revolute">
    <parent link="left_link"/>
    <child link="left_leg"/>
    <origin xyz="-0.093 0 0" rpy="0 0 0" />
    <axis xyz="0 0 1" />
    <limit effort="10" velocity="5.6548668" lower="-2.6179939" upper="2.6179939" />
  </joint>
  
  <transmission name = "trans_joint_leftleg">
    <type>transmission_interface/SimpleTransmission</type>
     <joint name ="left_leg_joint">
      <hardwareInterface>EfforJointInterface</hardwareInterface>
    </joint>
    <actuator name = "moto_joint_leftleg">
      <hardwareInterface>EfforJointInterface</hardwareInterface>
      <mechanicalReduction>1</mechanicalReduction>
    </actuator> 
  </transmission>
  
  
  
  <link name="foot_left_one" >
    <inertial>
      <origin xyz="-0.000214 -0.018536 0.013873" />
      <mass value="0.16710792"/>
      <inertia ixx="0.12079175"  ixy="-0.00079781067"  ixz="-0.00039322246" iyx="-0.00079781067" iyy="0.10885465" iyz="0.0070770117" izx="-0.00039322246" izy="0.0070770117" izz="0.041871103" />
    </inertial>
    <visual>
      <origin xyz="0 0 0" rpy="0 0 0" />
      <geometry>
        <!--box size="0.028652 0.08175 0.045"/-->
        <mesh filename="package://yegna_pkg/meshes/ankle1_l.STL"  scale="1 1 1"/>
      </geometry>
      <material name="Grey">
        <color rgba="0.20 0.20 0.20 1.0"/>
      </material>
    </visual>
    <collision>
      <geometry>
        <mesh filename="package://yegna_pkg/meshes/ankle1_l_coll.stl"  scale="1 1 1"/>
      </geometry>
    </collision>
  </link>

  <joint name="foot_left_joint" type="revolute">
    <parent link="left_leg"/>
    <child link="foot_left_one"/>
    <origin xyz="-0.093 0 0" rpy="3.14159 0 0" />
    <axis xyz="0 0 1" />
    <limit effort="10" velocity="5.6548668" lower="-2.6179939" upper="2.6179939" />
  </joint>
  
  <transmission name = "trans_joint_footleft">
    <type> transmission_interface/SimpleTransmission</type>
    <joint name = "foot_left_joint">
      <hardwareInterface>EffortJointInterface</hardwareInterface>
    </joint>
    <actuator name = "moto_joint_footleft" >
      <hardwareInterface>EffortJointInterface</hardwareInterface>
      <mechanicalReduction>1</mechanicalReduction>
    </actuator>   
  </transmission>
  
   <link name="foot_left_two">
    <inertial>
      <origin xyz="-0.025995 -0.009506 -0.000503" />
      <mass value="0.0794462"/>
      <inertia ixx="0.12079175"  ixy="-0.00079781067"  ixz="-0.00039322246" iyx="-0.00079781067" iyy="0.10885465" iyz="0.0070770117" izx="-0.00039322246" izy="0.0070770117" izz="0.041871103" />
    </inertial>
    <visual>
      <origin xyz="0 0 0" rpy="0 0 0" />
      <geometry>
        <!--box size="0.008 0.066 0.104"/-->
        <mesh filename="package://yegna_pkg/meshes/ankle2_l.STL"  scale="1 1 1"/>
      </geometry>
      <material name="Grey">
        <color rgba="0.20 0.20 0.20 1.0"/>
      </material>
    </visual>
    <collision>
      <geometry>
        <mesh filename="package://yegna_pkg/meshes/ankle2_l_coll.stl"  scale="1 1 1"/>
      </geometry>
    </collision>
  </link>

  <joint name="left_foot_joint_two" type="revolute">
    <parent link="foot_left_one"/>
    <child link="foot_left_two"/>
    <origin xyz="0 0 0" rpy="-1.5707963 0 0" />
    <axis xyz="0 0 1" />
    <limit effort="10" velocity="5.6548668" lower="-2.6179939" upper="2.6179939" />
  </joint>
  
  <transmission name = "trans_joint_leftfoot_two">
    <type>transmission_interface/SimpleTransmission</type>
    <joint name ="left_foot_joint_two">
     <hardwareInterface>EffortJointInterface</hardwareInterface>
    </joint>
    <actuator name = "moto_joint_leftfoot_two">
      <hardwareInterface>EffortJointInterface</hardwareInterface>
      <mechanicalReduction>1</mechanicalReduction>
    </actuator> 
  </transmission>
  
  

	  <!-- Right part of the robot -->
	  	  
	<link name="body_back_right">
    <inertial>
      <origin xyz="0 0 0" />
      <mass value="0.010"/>
      <inertia ixx="3.1081800"  ixy="-0.25460189"  ixz="2.0318174" iyy="6.3787776" iyz="0.16417863" izz="5.3316425" />
    </inertial>
    
    <visual>
      <origin xyz="0.0 0.0 0.0" rpy="0 0 0" />
      <geometry>
        <box size="0.001 0.001 0.001" />
      </geometry>
      <material name="Grey">
        <color rgba="0.20 0.20 0.20 1.0"/>
      </material>
    </visual>
    <collision>
      <geometry>
        <box size="0.001 0.001 0.001" />
      </geometry>
    </collision>
    
  </link>
  
  <joint name="body_back_right_joint" type="fixed">
    <parent link="body_link"/>
    <child link="body_back_right"/>
    <origin xyz="0 -0.06035 0" rpy="1.5707963 0 0" />
    <limit effort="2.8" velocity="5.6548668" lower="-2.6179939" upper="2.6179939" />
  </joint>
	  
	 
	  <link name="right_link">
	
	    <visual>

                <geometry>
                   <box size = "0.12 0.04 0.04"/>
                     
                </geometry>
               <!-- <origin xyz="0 0 -0.3" rpy="0 1.57075 0" /> -->
              <origin xyz="0.05 -0.010264 0.001394"/>
	    
             
	    	<material name="Blue">
	    	  <color rgba = "0.0 0.0 0.80 1.0"/>
	    	</material>  
	    </visual>
	   </link> 
	    
	  <joint name = "right_link_joint" type = "fixed">
	     <origin xyz="0 0 0" rpy="0 0 -1.5707963" />
         <axis xyz="0 0 1" />
	    <parent link="body_back_right" />
	    <child link="right_link" />
	  </joint> 
	  
	 <link name="right_leg" >
      <inertial>
      <origin xyz="0.053955 0.006548 -0.000592" />
      <mass value="0.070309794"/>
      <inertia ixx="0.093369608"  ixy="-0.00093567395"  ixz="-0.00023992085" iyx="-0.00093567395" iyy="0.046295534" 
               iyz="-0.012858493" izx="-0.00023992085" izy="-0.012858493" izz="0.11351516" />
     </inertial>
    <visual>
      <origin xyz="0 0 0" rpy="0 0 0" />
      <geometry>
        <!--box size="0.093 0.035 0.045"/-->
        <mesh filename="package://yegna_pkg/meshes/tibia_r.STL"  scale="1 1 1"/>
      </geometry>
      <material name="Grey">
        <color rgba="0.20 0.20 0.20 1.0"/>
      </material>
    </visual>
    <collision>
      <geometry>
        <mesh filename="package://yegna_pkg/meshes/tibia_r_coll.stl"  scale="1 1 1"/>
      </geometry>
    </collision>

  </link> 
  
  <joint name="right_leg_joint" type="revolute">
    <parent link="right_link"/>
    <child link="right_leg"/>
    <origin xyz="0.093 0 0" rpy="0 0 0" />
    <axis xyz="0 0 1" />
    <limit effort="10" velocity="5.6548668" lower="-2.6179939" upper="2.6179939" />
  </joint>
  
  <transmission name = "trans_joint_rightleg">
    <type>transmission_interface/SimpleTransmission</type>
    <joint name ="right_leg_joint">
     <hardwareInterface>EffortJointInterface</hardwareInterface>
    </joint>
    <actuator name = "moto_joint_rightleg">
      <hardwareInterface>EffortJointInterface</hardwareInterface>
      <mechanicalReduction>1</mechanicalReduction>
    </actuator> 
  </transmission>
  
	 
	  
  <link name="foot_right_one" >
    <inertial>
      <origin xyz="-0.000214 -0.018536 -0.013873" />
      <mass value="0.16710792"/>
      <inertia ixx="0.12079175"  ixy="-0.00079781067"  ixz="-0.00039322246" iyx="-0.00079781067" iyy="0.10885465" 
               iyz="0.0070770117" izx="-0.00039322246" izy="0.0070770117" izz="0.041871103" />
    </inertial>
    <visual>
      <origin xyz="0 0 0" rpy="0 0 0" />
      <geometry>
        <!--box size="0.028652 0.08175 0.045"/-->
        <mesh filename="package://yegna_pkg/meshes/ankle1_r.STL"  scale="1 1 1"/>
      </geometry>
      <material name="Grey">
        <color rgba="0.20 0.20 0.20 1.0"/>
      </material>
    </visual>
    <collision>
      <geometry>
        <mesh filename="package://yegna_pkg/meshes/ankle1_r_coll.stl"  scale="1 1 1"/>
      </geometry>
    </collision>

  </link>	  
  <joint name="foot_right_joint_one" type="revolute">
    <parent link="right_leg"/>
    <child link="foot_right_one"/>
    <origin xyz="0.093 0 0" rpy="3.14159 0 0" />
    <axis xyz="0 0 1" />
    <limit effort="10" velocity="5.6548668" lower="-2.6179939" upper="2.6179939" />
  </joint>
  
  <transmission name = "trans_joint_rightfoot_one">
    <type>transmission_interface/SimpleTransmission</type>
    <joint name ="foot_right_joint_one">
     <hardwareInterface>EffortJointInterface</hardwareInterface>
    </joint>
    <actuator name = "moto_joint_rightfoot_one">
      <hardwareInterface>EffortJointInterface</hardwareInterface>
      <mechanicalReduction>1</mechanicalReduction>
    </actuator> 
  </transmission>
  
  <link name="foot_right_two" >
    <inertial>
      <origin xyz="0.025995 -0.009506 -0.000503" />
      <mass value="0.0794462"/>
      <inertia ixx="0.12079175"  ixy="-0.00079781067"  ixz="-0.00039322246" iyx="-0.00079781067" iyy="0.10885465" 
               iyz="0.0070770117" izx="-0.00039322246" izy="0.0070770117" izz="0.041871103" />
    </inertial>
    <visual>
      <origin xyz="0 0 0" rpy="0 0 0" />
      <geometry>
        <!--box size="0.008 0.066 0.104"/-->
        <mesh filename="package://yegna_pkg/meshes/ankle2_r.STL"  scale="1 1 1"/>
      </geometry>
      <material name="Grey">
        <color rgba="0.20 0.20 0.20 1.0"/>
      </material>
    </visual>
    <collision>
      <geometry>
        <mesh filename="package://yegna_pkg/meshes/ankle2_r_coll.stl"  scale="1 1 1"/>
      </geometry>
    </collision>

  </link>
  
  <joint name="right_foot_joint_two" type="revolute">
    <parent link="foot_right_one"/>
    <child link="foot_right_two"/>
    <origin xyz="0 0 0" rpy="-1.5707963 0 0" />
    <axis xyz="0 0 1" />
    <limit effort="10" velocity="5.6548668" lower="-2.6179939" upper="2.6179939" />
  </joint>
  
  <transmission name = "trans_joint_rightfoot_two">
    <type>transmission_interface/SimpleTransmission</type>
    <joint name ="right_foot_joint_two">
     <hardwareInterface>EffortJointInterface</hardwareInterface>
    </joint>
    <actuator name = "moto_joint_rightfoot_two">
      <hardwareInterface>EffortJointInterface</hardwareInterface>
      <mechanicalReduction>1</mechanicalReduction>
    </actuator> 
  </transmission>
  
</robot>  
